<mujoco model="discrete_fish">
  <compiler angle="degree" coordinate="local" inertiafromgeom="true"/>
  <option timestep="0.01" iterations="4" />
  <custom>
    <!-- brax custom params -->
    <numeric data="0.0 0.0 0.0" name="init_qpos"/>
    <numeric data="1000" name="constraint_limit_stiffness"/>
    <numeric data="4000" name="constraint_stiffness"/>
    <numeric data="10" name="constraint_ang_damping"/>
    <numeric data="20" name="constraint_vel_damping"/>
    <numeric data="0.5" name="joint_scale_pos"/>
    <numeric data="0.2" name="joint_scale_ang"/>
    <numeric data="0.0" name="ang_damping"/>
    <numeric data="1" name="spring_mass_scale"/>
    <numeric data="1" name="spring_inertia_scale"/>
    <numeric data="15" name="solver_maxls"/>
  </custom>
  <default>
    <joint armature="1" damping="1" limited="true"/>
    <geom contype="0" conaffinity="0" condim="3" density="5.0" friction="1 0.5 0.5" rgba="0.4 0.33 0.26 1.0"/>
  </default>
  <asset>
    <texture builtin="gradient" height="100" rgb1="1 1 1" rgb2="0 0 0" type="skybox" width="100"/>
    <texture builtin="flat" height="1278" mark="cross" markrgb="1 1 1" name="texgeom" random="0.01" rgb1="0.8 0.6 0.4" rgb2="0.8 0.6 0.4" type="cube" width="127"/>
    <texture builtin="checker" height="100" name="texplane" rgb1="0 0 0" rgb2="0.8 0.8 0.8" type="2d" width="100"/>
    <material name="MatPlane" reflectance="0.5" shininess="1" specular="1" texrepeat="60 60" texture="texplane"/>
    <material name="geom" texture="texgeom" texuniform="true"/>
  </asset>
  <worldbody>
    <light cutoff="100" diffuse="1 1 1" dir="-0 0 -1.3" directional="true" exponent="1" pos="0 0 1.3" specular=".1 .1 .1"/>
    <geom conaffinity="1" condim="3" material="MatPlane" name="floor" pos="0 0 0" size="4000 4000 40" type="plane"/>
    <body name="torso" pos="0 0 0.2">
      <geom name="torso_geom" size="0.2" type="sphere" contype="2" conaffinity="2"/>
      <joint axis="1 0 0"  name="move_joint_x" pos="0 0 0" range="-180 180" type="slide"/>
      <joint axis="0 1 0"  name="move_joint_y" pos="0 0 0" range="-180 180" type="slide"/>
      <joint axis="0 0 1"  name="rotate_joint" pos="0 0 0" range="-360 360" type="hinge"/>
      <body name="camera" pos="0.2 0.0 0" quat="0.70710677 0 -0.7071068 0" >
        <geom name="sensor_0_geom" size="0.1" type="sphere"  rgba="1 0 0 1"/> <!-- Blue color -->
      </body>

    </body>
  </worldbody>
    <actuator>
      <motor ctrllimited="true" ctrlrange="0.0 1.0" joint="move_joint_y" gear="50.0" forcelimited="true" forcerange="0.0 .1"/>
    <motor ctrllimited="true" ctrlrange="0.0 1.0" joint="move_joint_x" gear="50.0" forcelimited="true" forcerange="0.0 .1"/>
    <motor ctrllimited="true" ctrlrange="0.0 1.0" joint="move_joint_x" gear="-50.0" forcelimited="true" forcerange="0.0 .1"/>
    <motor ctrllimited="true" ctrlrange="0.0 1.0" joint="move_joint_y" gear="-50.0" forcelimited="true" forcerange="0.0 .1"/>
  </actuator>




</mujoco>